Workbook

Sheet Anleitung
A1: KV-Monitoring — Normen und Prüfanforderungen
A2: Stand: Stammdaten aus KV-Monitoring.html (Commit dd4251e)
A4: Blatt | B4: Zeilen | C4: Was drinsteht
A5: Normen | B5: 121 | C5: Alle Normen und Prüfprogramme mit Typ, Prüfungsart, SAP-Code, Preis, Kennzeichnungs-/BDA-Kennzeichen und Bemerkung. „Verwendet in PG“ zählt per Formel, in wie vielen Prüfgrundlagen die Norm steckt — 0 heißt: nirgends referenziert.
A6: Anwendungsbereiche | B6: 28 | C6: Untergliederung einzelner Normen (z. B. „Filigrane Tische“) mit eigenem Preis.
A7: Prüfanforderungen | B7: 179 | C7: Die Arbeitsliste: eine Zeile je geforderter Prüfung — Produkt × Norm × Prüfblock, mit Kosten für die 1. Prüfung und je weiterem Produkt. Leere Kosten sind gelb hinterlegt (im Tool „Preis auf Anfrage“).
A8: Prüfgrundlagen | B8: 185 | C8: Eine Zeile je Produkt, mit Anzahl Muster, Bearbeitungsdauer und den drei Blöcken Sicherheit/Norm, FFU und NGO/StiWa. Die Summenspalten sind Formeln über das Blatt „Prüfanforderungen“. Die Spalte „Status“ markiert gelb, wo noch etwas fehlt: keine Norm zugeordnet oder 0 € hinterlegt.
A9: MAK-Anforderungen | B9: 193 | C9: Der LIDL-Materialanforderungskatalog mit Anforderung, Norm EU/US und Mindest-Prüfnachweis.
A12: Funktionen in dieser Datei
A13: • | C13: Jede Kopfzeile hat einen Autofilter samt Suchfeld — das ersetzt die Filterkette Bereich → Warengruppe → Produkt und die Volltextsuche des Tools.
A14: • | C14: Die Kopfzeile ist fixiert; beim Scrollen bleiben die Spaltentitel stehen.
A15: • | C15: Summen und Zählungen stehen als Formeln (SUMIFS/COUNTIFS) in der Datei, nicht als eingefrorene Werte — wer eine Kostenzeile ändert, sieht die neue Blocksumme sofort.
A16: • | C16: „Preis auf Anfrage“ entsteht wie im Tool: hat keine einzige Norm eines Blocks einen Betrag, steht dort kein 0 €, sondern der Text.
A17: • | C17: Die technischen IDs stehen in ausgeblendeten Spalten (Normen: Q, Prüfanforderungen: P, Prüfgrundlagen: V). Sie verknüpfen die Blätter — bitte nicht löschen, sonst brechen die Formeln.
A18: • | C18: Die Datei ist ein Auszug zum Lesen, Filtern und Weitergeben. Gepflegt wird weiterhin im Tool: Änderungen hier fließen nicht zurück.

Sheet Normen
A1: Alle Normen und Prüfprogramme aus dem Reiter „Normen“. Kopfzeile filtern/sortieren wie gewohnt; „Verwendet in PG“ zählt live, in wie vielen Prüfgrundlagen die Norm referenziert ist.
A2: Norm / Prüfprogramm | B2: Titel | C2: Typ | D2: Prüfungsart | E2: SAP-Code | F2: Preis | G2: Kennz. | H2: BDA | I2: LIDL-Block | J2: Anw.-bereiche | K2: Anwendungsbereiche | L2: Bemerkung | M2: PDF-Datei | N2: Hochgeladen | O2: Volltext | P2: Verwendet in PG | Q2: ID
A3: 004_PPM_FFU | C3: FFU-Prüfprogramm (PPM_FFU) | G3: Nein | H3: Nein | I3: sicherheitNorm | J3: 0 | O3: Nein | P3: =COUNTIF(Prüfanforderungen!$G$3:$G$181,$A3) -> 1 | Q3: 5c4e2c8f-7c83-4357-861a-685d033cad40
A4: 038_PPM_FFU | C4: FFU-Prüfprogramm (PPM_FFU) | G4: Nein | H4: Nein | I4: sicherheitNorm | J4: 0 | O4: Nein | P4: =COUNTIF(Prüfanforderungen!$G$3:$G$181,$A4) -> 1 | Q4: de17f5f0-3630-4b44-973e-107fdeefaafd
A5: 064_PPM | C5: Prüfprogramm (PPM) | G5: Nein | H5: Nein | I5: sicherheitNorm | J5: 0 | O5: Nein | P5: =COUNTIF(Prüfanforderungen!$G$3:$G$181,$A5) -> 1 | Q5: 85202135-425b-497e-a036-dfb3fdc19489
A6: 102_PPM | C6: Prüfprogramm (PPM) | G6: Nein | H6: Nein | I6: sicherheitNorm | J6: 0 | L6: PSA beachten! | ggf. EE | Multiwinkel / Lineal / Zollstock / usw. | nicht trivial, wenn Verwendung auf Herd möglich | HG | O6: Nein | P6: =COUNTIF(Prüfanforderungen!$G$3:$G$181,$A6) -> 70 | Q6: 3256bf4d-e3db-4546-baa1-2197c227fc2f
A7: 102_PPM in Anlehnung an EK5.2 PA 80-4.2.1 -> Punkt 2 -> Punkt 3 (ohne 3.6) -> Punkt 4.1 | C7: Prüfprogramm (PPM) | G7: Nein | H7: Nein | I7: sicherheitNorm | J7: 0 | L7: ggf. Auslobung nach DIN 6439 DIN 6440 & DIN 6441 DIN 7216 | O7: Nein | P7: =COUNTIF(Prüfanforderungen!$G$3:$G$181,$A7) -> 1 | Q7: 20761c1b-d111-4943-b1d9-e11656799d04
A8: 102_PPM + Belastungsprüfung | C8: Prüfprogramm (PPM) | G8: Nein | H8: Nein | I8: sicherheitNorm | J8: 0 | O8: Nein | P8: =COUNTIF(Prüfanforderungen!$G$3:$G$181,$A8) -> 1 | Q8: fa0a5f3f-754a-4ba8-93a4-c2dbeda77b95
A9: 102_PPM + Belastungsprüfung (1,5-fache Nennlast für 60min.) | C9: Prüfprogramm (PPM) | G9: Nein | H9: Nein | I9: sicherheitNorm | J9: 0 | L9: für alle Eimer, die auf einer Baustelle verwendet werden können | O9: Nein | P9: =COUNTIF(Prüfanforderungen!$G$3:$G$181,$A9) -> 1 | Q9: e2fa8876-d62b-476a-811a-d17570291269
A10: 102_PPM + Zugprüfung in Anlehnung an DIN EN ISO 2307 | C10: Prüfprogramm (PPM) | G10: Nein | H10: Nein | I10: sicherheitNorm | J10: 0 | O10: Nein | P10: =COUNTIF(Prüfanforderungen!$G$3:$G$181,$A10) -> 1 | Q10: a0b303e2-e5d4-4d78-9348-947103a562fe
A11: 102_PPM in Anlehnung an DIN EN 71-1 | C11: Prüfprogramm (PPM) | G11: Nein | H11: Nein | I11: sicherheitNorm | J11: 0 | O11: Nein | P11: =COUNTIF(Prüfanforderungen!$G$3:$G$181,$A11) -> 1 | Q11: 0a02560c-7778-4400-ad87-0709f2a4825e
A12: 102_PPM_TGS_REV_B mit Belastung in Anlehnung an HHJ126550_PPM_TGS_V5_Pet Leash | C12: Norm (extern) | G12: Nein | H12: Nein | I12: sicherheitNorm | J12: 0 | O12: Nein | P12: =COUNTIF(Prüfanforderungen!$G$3:$G$181,$A12) -> 1 | Q12: 3349ba18-9e5d-4d33-a0c6-54a18dc53ba8
A13: 110_PPM_FFU | C13: FFU-Prüfprogramm (PPM_FFU) | G13: Nein | H13: Nein | I13: sicherheitNorm | J13: 0 | O13: Nein | P13: =COUNTIF(Prüfanforderungen!$G$3:$G$181,$A13) -> 1 | Q13: a8613652-bb0a-4b32-9ad7-11d42bb50b26
A14: 111_PPM | C14: Prüfprogramm (PPM) | G14: Nein | H14: Nein | I14: sicherheitNorm | J14: 0 | O14: Nein | P14: =COUNTIF(Prüfanforderungen!$G$3:$G$181,$A14) -> 1 | Q14: 1ab095f7-924f-4566-95f3-abd6f6792a29
A15: 113_PPM | C15: Prüfprogramm (PPM) | G15: Nein | H15: Nein | I15: sicherheitNorm | J15: 0 | L15: Artikelkategorie bei LIDL beachten! | O15: Nein | P15: =COUNTIF(Prüfanforderungen!$G$3:$G$181,$A15) -> 0 | Q15: 6d8434d0-8905-4506-9cb2-8af84e8ecc93
A16: 131_PPM_TGS_REV_A | C16: Norm (extern) | G16: Nein | H16: Nein | I16: sicherheitNorm | J16: 0 | O16: Nein | P16: =COUNTIF(Prüfanforderungen!$G$3:$G$181,$A16) -> 1 | Q16: 91198e93-ecd8-48b0-8e49-4ea7ad96aa61
A17: 163_PPM_FFU | C17: FFU-Prüfprogramm (PPM_FFU) | G17: Nein | H17: Nein | I17: sicherheitNorm | J17: 0 | L17: in Anlehnung an StiWa 06/2014 | O17: Nein | P17: =COUNTIF(Prüfanforderungen!$G$3:$G$181,$A17) -> 1 | Q17: cf713cbc-1e22-47cc-92dc-e9f6f482519e
A18: 178_PPM_FFU | C18: FFU-Prüfprogramm (PPM_FFU) | G18: Nein | H18: Nein | I18: sicherheitNorm | J18: 0 | O18: Nein | P18: =COUNTIF(Prüfanforderungen!$G$3:$G$181,$A18) -> 0 | Q18: e6fa722c-4f1e-448c-b636-75cfd6296881
A19: 515_PPM_FFU_REV_A_Schraubstock | C19: FFU-Prüfprogramm (PPM_FFU) | G19: Nein | H19: Nein | I19: sicherheitNorm | J19: 0 | O19: Nein | P19: =COUNTIF(Prüfanforderungen!$G$3:$G$181,$A19) -> 1 | Q19: 964cbca6-aff5-4621-85e6-772dcfa213f4
A20: 516_PPM_FFU | C20: FFU-Prüfprogramm (PPM_FFU) | G20: Nein | H20: Nein | I20: sicherheitNorm | J20: 0 | O20: Nein | P20: =COUNTIF(Prüfanforderungen!$G$3:$G$181,$A20) -> 1 | Q20: fa56a1ac-10ec-4acb-894c-ec99116521df
A21: 519_PPM_FFU | C21: FFU-Prüfprogramm (PPM_FFU) | G21: Nein | H21: Nein | I21: sicherheitNorm | J21: 0 | O21: Nein | P21: =COUNTIF(Prüfanforderungen!$G$3:$G$181,$A21) -> 2 | Q21: 527ec958-ca26-4d8c-8d66-fb254651c802
A22: Akkusicherheitskurzcheck (163_PPM) | C22: Prüfprogramm (PPM) | E22: 163_PPM_TS | G22: Nein | H22: Nein | J22: 0 | O22: Nein | P22: =COUNTIF(Prüfanforderungen!$G$3:$G$181,$A22) -> 0 | Q22: bb9249f2-f42b-489c-be9b-2def4cfef879
A23: DIN 1193 (Latthammer DIN 7239) (Schlosserhammer DIN 1041), (Maurerhammer DIN 5108), (Gummihammer DIN 5128), (Klauenhammer ???) (Holzstiel bis 2kg DIN 5111, Holzstiel über 2kg DIN 5112) (Holz- u Kunststoffstiele EK5 AK2 PA 80-8.1.1 2017-10) | C23: Norm (extern) | E23: MECH_S_NORM_TS | G23: Nein | H23: Nein | I23: sicherheitNorm | J23: 0 | O23: Nein | P23: =COUNTIF(Prüfanforderungen!$G$3:$G$181,$A23) -> 1 | Q23: 1a3e2b97-ede0-4478-9ed7-9c214a19faa2
A24: DIN 5117 | C24: Norm (extern) | G24: Nein | H24: Nein | I24: sicherheitNorm | J24: 0 | O24: Nein | P24: =COUNTIF(Prüfanforderungen!$G$3:$G$181,$A24) -> 1 | Q24: ccc203b0-c405-41e9-ae1a-b09b6bb01a8f
A25: DIN 968 & DIN EN ISO 1478 & DIN EN ISO 3506-4 | C25: Norm (extern) | G25: Nein | H25: Nein | I25: sicherheitNorm | J25: 0 | O25: Nein | P25: =COUNTIF(Prüfanforderungen!$G$3:$G$181,$A25) -> 1 | Q25: b124db66-45a3-4f4e-9917-2a0eeafe1718
A26: DIN 976-1 | C26: Norm (extern) | G26: Nein | H26: Nein | I26: sicherheitNorm | J26: 0 | O26: Nein | P26: =COUNTIF(Prüfanforderungen!$G$3:$G$181,$A26) -> 1 | Q26: f9d4394d-4e61-4682-bc19-75e3080add0a
A27: DIN EN 10230-1 &DIN EN 14592 | C27: Norm (extern) | G27: Nein | H27: Nein | I27: sicherheitNorm | J27: 0 | O27: Nein | P27: =COUNTIF(Prüfanforderungen!$G$3:$G$181,$A27) -> 1 | Q27: 866c158c-821d-4beb-ad86-2039ed44b8ae
A28: DIN EN 12521:2023 | C28: Norm (extern) | G28: Nein | H28: Nein | I28: sicherheitNorm | J28: 0 | O28: Nein | P28: =COUNTIF(Prüfanforderungen!$G$3:$G$181,$A28) -> 1 | Q28: 3eb8ccc2-1861-425b-8f4d-f792f2f82848
A29: DIN EN 12521:2023 / Anforderungen für filigrane Tische | C29: Norm (extern) | G29: Nein | H29: Nein | J29: 0 | O29: Nein | P29: =COUNTIF(Prüfanforderungen!$G$3:$G$181,$A29) -> 2 | Q29: 25e078d7-7dcb-444c-a798-182580a429ec
A30: DIN EN 12546-1 | C30: Norm (extern) | G30: Nein | H30: Nein | I30: sicherheitNorm | J30: 0 | O30: Nein | P30: =COUNTIF(Prüfanforderungen!$G$3:$G$181,$A30) -> 3 | Q30: fa058e46-5aea-4158-ac82-fd4861bfd1fc
A31: DIN EN 13120 (inkl. DIN EN 16434) | C31: Norm (extern) | G31: Nein | H31: Nein | I31: sicherheitNorm | J31: 0 | L31: Musterzahl beachten! + zusätzlich 12 Sicherheitseinrichtungen! (abs. Minimum 8) Ablauf in der Norm beachten!! UV-Belichtung notwendig nach DIN EN 16434 Muster Asien Rollo DIN EN 13120 Abschn 8 (inkl. DIN EN 16434) 2x größter und 2x kleinster Style wird für Prüfung benötigt + 4x Sicherheitsclips "Guarantee letter-General" ausfüllen senden + in Versandkarton legen + „Dispatch samples Form 寄样单Fion-General“ auf Versandkarton kleben Kosten 1936€ (Lidl) 25 AT Muster Tstn: 1x je Style DIN EN 13120 Abschn 15 (13.12.24 SH) | O31: Nein | P31: =COUNTIF(Prüfanforderungen!$G$3:$G$181,$A31) -> 1 | Q31: a362c1e5-d2bd-408e-99e7-ea7b3230c740
A32: DIN EN 13120 Pkt 8.2.2 (EN 16433) + 15 | C32: Norm (extern) | G32: Nein | H32: Nein | I32: sicherheitNorm | J32: 0 | L32: (ohne Schlaufe) Asien | O32: Nein | P32: =COUNTIF(Prüfanforderungen!$G$3:$G$181,$A32) -> 1 | Q32: f795ebb9-7e34-4c53-9cc8-54a10d0d5459
A33: DIN EN 13834 | C33: Norm (extern) | G33: Nein | H33: Nein | I33: sicherheitNorm | J33: 0 | O33: Nein | P33: =COUNTIF(Prüfanforderungen!$G$3:$G$181,$A33) -> 2 | Q33: fa7e6f3d-428b-40d3-9800-83dea3261fb5
A34: DIN EN 13843 | C34: Norm (extern) | G34: Nein | H34: Nein | I34: sicherheitNorm | J34: 0 | O34: Nein | P34: =COUNTIF(Prüfanforderungen!$G$3:$G$181,$A34) -> 1 | Q34: f0fc9126-1d6b-44af-b542-64179693933b
A35: DIN EN 14468-1 | C35: Norm (extern) | G35: Nein | H35: Nein | I35: sicherheitNorm | J35: 0 | O35: Nein | P35: =COUNTIF(Prüfanforderungen!$G$3:$G$181,$A35) -> 1 | Q35: a06c6fc6-470c-4018-8fc7-130a7d953f0b
A36: DIN EN 14749 | C36: Norm (extern) | E36: MECH_S_NORM_TS | G36: Nein | H36: Nein | I36: sicherheitNorm | J36: 0 | O36: Nein | P36: =COUNTIF(Prüfanforderungen!$G$3:$G$181,$A36) -> 1 | Q36: a982a9b1-93b2-4bd1-ba5a-8e6f4511692c
A37: DIN EN 17885 | C37: Norm (extern) | G37: Nein | H37: Nein | I37: sicherheitNorm | J37: 0 | O37: Nein | P37: =COUNTIF(Prüfanforderungen!$G$3:$G$181,$A37) -> 1 | Q37: 4528b97e-6f0d-46f9-ac90-346abb9188ac
A38: DIN EN 1860-1 | C38: Norm (extern) | G38: Nein | H38: Nein | I38: sicherheitNorm | J38: 0 | L38: Gasgeräteverordnung! CE-Zeichen! KE nötig. Prüfung über Asien | Für GS-Projekte EK-Beschlussliste EK5/AK8 beachten! | O38: Nein | P38: =COUNTIF(Prüfanforderungen!$G$3:$G$181,$A38) -> 2 | Q38: 096ca6dc-0cba-4b64-b0c3-5c0fae23aa75
A39: DIN EN 1992-4 | C39: Norm (extern) | G39: Nein | H39: Nein | I39: sicherheitNorm | J39: 0 | O39: Nein | P39: =COUNTIF(Prüfanforderungen!$G$3:$G$181,$A39) -> 1 | Q39: a9ecaab4-bb8d-4698-b17b-7bb19724c94a
A40: DIN EN 20957 | C40: Norm (extern) | G40: Nein | H40: Nein | I40: sicherheitNorm | J40: 0 | O40: Nein | P40: =COUNTIF(Prüfanforderungen!$G$3:$G$181,$A40) -> 1 | Q40: fc88926a-57b0-4cc2-b4db-d7cdf571913c
...

Sheet Anwendungsbereiche
A1: Anwendungsbereiche einzelner Normen (z. B. „Filigrane Tische“) mit eigenem Preis — in der Prüfgrundlage wird je Referenz einer davon ausgewählt.
A2: Norm | B2: Titel der Norm | C2: Prüfungsart | D2: Anwendungsbereich | E2: Beschreibung | F2: Preis
A3: DIN EN 12521:2023 | B3: Möbel - Sicherheit, Festigkeit und Dauerhaltbarkeit - Anforderungen an Tische im Wohnbereich | C3: Sicherheit-/Normprüfung | D3: Alle anderen Tische
A4: DIN EN 12521:2023 | B4: Möbel - Sicherheit, Festigkeit und Dauerhaltbarkeit - Anforderungen an Tische im Wohnbereich | C4: Sicherheit-/Normprüfung | D4: Filigrane Tische
A5: DIN EN 12521:2023 | B5: Möbel - Sicherheit, Festigkeit und Dauerhaltbarkeit - Anforderungen an Tische im Wohnbereich | C5: Sicherheit-/Normprüfung | D5: Tische mit einer Höhe ≤600mm oder Tische mit einer Plattenfläche ≤0,3m2
A6: DIN EN 581-2 2017-01 | B6: Außenmöbel – Sitzmöbel und Tische für den Camping-, Wohn- und Objektbereich | D6: Campingbereich
A7: DIN EN 581-2 2017-01 | B7: Außenmöbel – Sitzmöbel und Tische für den Camping-, Wohn- und Objektbereich | D7: Objektbereich
A8: DIN EN 581-2 2017-01 | B8: Außenmöbel – Sitzmöbel und Tische für den Camping-, Wohn- und Objektbereich | D8: Wohnbereich
A9: DIN EN 581-3 2017 | B9: Außenmöbel - Sitzmöbel und Tische für den Camping-, Wohn- und Objektbereich - Teil 3: Mechanische Sicherheitsanforderungen für Tische | D9: Allgemeines | E9: 5.1 Die Anforderungen nach EN 581-1:2017 müssen vor und nach der Durchführung der Prüfungen der Festigkeit, Dauerhaltbarkeit und Standsicherheit erfüllt sein. Glastischplatten müssen den Anforderungen nach EN 12150-1:2015, Abschnitt 8, Prüfung der Bruchstruktur, oder dem Bruchverhalten (β) vom Typ B oder Typ C nach EN 12600:2002 entsprechen. Öffnungen für Sonnenschirme in der Glastischplatte müssen geschützt sein, um einen Kontakt zwischen Metall und Glas zu vermeiden.
A10: DIN EN 581-3 2017 | B10: Außenmöbel - Sitzmöbel und Tische für den Camping-, Wohn- und Objektbereich - Teil 3: Mechanische Sicherheitsanforderungen für Tische | D10: Anforderungen | E10: 5.2.2 Die Anforderungen an die Sicherheit, Festigkeit und Dauerhaltbarkeit sind eingehalten, wenn nach der Prüfung nach Tabelle 1: a) kein Teil, Bauteil oder Verbindungselement Brüche aufweist; b) sich kein bestimmungsgemäß festsitzendes Verbindungselement gelöst hat; c) der Tisch nach Entfernung der Prüflasten seine Funktionen erfüllt. Das Produkt darf während der Standsicherheitsprüfungen nicht umkippen.
A11: DIN EN 581-3 2017 | B11: Außenmöbel - Sitzmöbel und Tische für den Camping-, Wohn- und Objektbereich - Teil 3: Mechanische Sicherheitsanforderungen für Tische | D11: Anforderungen an die Sicherheit, Festigkeit und Dauerhaltbarkeit | E11: 5
A12: DIN EN 581-3 2017 | B12: Außenmöbel - Sitzmöbel und Tische für den Camping-, Wohn- und Objektbereich - Teil 3: Mechanische Sicherheitsanforderungen für Tische | D12: Anhang A | E12: Anhang A (informativ) Kaufinformation (Leitfaden) Um dem Verbraucher vor dem Kauf die Wahl eines Produktes im Hinblick auf die vorgesehene Nutzung zu ermöglichen, sollte die Kaufinformation ohne Öffnen der Verpackung verfügbar sein. Folgende Angaben sollten enthalten sein:  Bezeichnung des Produktes;  Produktmerkmale, z. B. Maße, Angaben zur Aufbewahrung, Pflege usw.;  Nutzungsbedingungen für das Produkt (Camping-, Wohn- oder Objektbereich);  ein Warnhinweis, falls der Tisch, der ein Loch für einen Sonnenschirm hat, nicht dafür vorgesehen ist, einen Sonnenschirm zu halten. Licensed to SGS-TÜV Saar GmbH - GLOBALNORM ILNAS eShop 2017 02578 / Max. Networking : 1 / downloaded : 2017-05-23 NOT FOR COMMERCIAL USE OR REPRODUCTION ILNAS-EN 581-3:2017
A13: DIN EN 581-3 2017 | B13: Außenmöbel - Sitzmöbel und Tische für den Camping-, Wohn- und Objektbereich - Teil 3: Mechanische Sicherheitsanforderungen für Tische | D13: Anwendungsbereich | E13: 1 Diese Europäische Norm legt die Mindestanforderungen an die Sicherheit, Festigkeit und Dauerhaltbarkeit für alle Arten von Außentischen für Erwachsene, unabhängig von Werkstoffen, Design/Konstruktion oder Herstellungsprozessen, fest. Sie gilt nicht für öffentlich aufgestellte Straßenmöbel. Die Norm enthält mit Ausnahme der Prüfungen der Standsicherheit keine Beurteilung der Eignung der in Tischen enthaltenen Aufbewahrungsmöglichkeiten. Sie enthält keine Anforderungen an die Dauerhaltbarkeit von Rollen/Rädern und an Mechanismen zur Höhenverstellung. Sie enthält keine Anforderungen an die elektrische Sicherheit. Sie enthält keine Anforderungen an die Alterungsbeständigkeit und an durch Licht, Temperatur und Feuchtigkeit verursachte Qualitätsminderungen.
A14: DIN EN 581-3 2017 | B14: Außenmöbel - Sitzmöbel und Tische für den Camping-, Wohn- und Objektbereich - Teil 3: Mechanische Sicherheitsanforderungen für Tische | D14: Außenmöbel für den Campingbereich | E14: 3.3 Außenmöbel, das klappbar oder zerlegbar und leicht ist, sowie für die Nutzung beim Camping und auf Reisen vorgesehen ist
A15: DIN EN 581-3 2017 | B15: Außenmöbel - Sitzmöbel und Tische für den Camping-, Wohn- und Objektbereich - Teil 3: Mechanische Sicherheitsanforderungen für Tische | D15: Außenmöbel für den Objektbereich | E15: 3.1 Außenmöbel, das für die nicht private Nutzung an öffentlich zugänglichen Stellen vorgesehen ist
A16: DIN EN 581-3 2017 | B16: Außenmöbel - Sitzmöbel und Tische für den Camping-, Wohn- und Objektbereich - Teil 3: Mechanische Sicherheitsanforderungen für Tische | D16: Außenmöbel für den Wohnbereich | E16: 3.2 Außenmöbel, das für die private Nutzung ohne öffentlichen Zugang vorgesehen ist Licensed to SGS-TÜV Saar GmbH - GLOBALNORM ILNAS eShop 2017 02578 / Max. Networking : 1 / downloaded : 2017-05-23 NOT FOR COMMERCIAL USE OR REPRODUCTION ILNAS-EN 581-3:2017 EN 581-3:2017 (D) 5
A17: DIN EN 581-3 2017 | B17: Außenmöbel - Sitzmöbel und Tische für den Camping-, Wohn- und Objektbereich - Teil 3: Mechanische Sicherheitsanforderungen für Tische | D17: Begriffe | E17: 3 Für die Anwendung dieses Dokuments gelten die folgenden Begriffe.
A18: DIN EN 581-3 2017 | B18: Außenmöbel - Sitzmöbel und Tische für den Camping-, Wohn- und Objektbereich - Teil 3: Mechanische Sicherheitsanforderungen für Tische | D18: Festgelegte Kraft, N | E18: 6.3.1 a) Hauptplatte bei Tischen mit einer Höhe ≤ 950 mm 300 750 1 000 b) Hauptplatte bei Tischen mit einer Höhe > 950 mm – 500 500 Zyklen 10 10 10 2. Vertikale statische Belastung der Hauptplatte Für Tische mit einer Fläche der Tischplatte ≤ 0,25 m 2 b EN 1730:2012,
A19: DIN EN 581-3 2017 | B19: Außenmöbel - Sitzmöbel und Tische für den Camping-, Wohn- und Objektbereich - Teil 3: Mechanische Sicherheitsanforderungen für Tische | D19: Festgelegte Kraft, N | E19: 6.3.1 Zyklen 150 10 300 10 500 10 3. Zusätzliche vertikale statische Belastungsprüfung für Hauptplatten, welche länger als 1 600 mm sind EN 1730:2012,
A20: DIN EN 581-3 2017 | B20: Außenmöbel - Sitzmöbel und Tische für den Camping-, Wohn- und Objektbereich - Teil 3: Mechanische Sicherheitsanforderungen für Tische | D20: Festgelegte Kraft, N | E20: 6.3.2 Zyklen 500 10 750 10 1 000 10 4. Vertikale statische Belastung der Ergänzungsplatte EN 1730:2012,
... A30: DIN EN 581-3 2017 | B30: Außenmöbel - Sitzmöbel und Tische für den Camping-, Wohn- und Objektbereich - Teil 3: Mechanische Sicherheitsanforderungen für Tische | D30: Straßenmöbel | E30: 3.4 Außenmöbel zur Benutzung im öffentlichen Raum, das dauerhaft am Boden oder einer Konstruktion (z. B. Bushaltestelle, Wand usw.) befestigt ist oder nicht von Hand entfernt werden kann

Sheet Prüfanforderungen
A1: Eine Zeile je geforderter Prüfung: welches Produkt braucht welche Norm, in welchem Block, zu welchem Preis. Das ist die Arbeitsliste — hier nach Bereich, Warengruppe, Produkt oder Norm filtern. Leere Kosten = „Preis auf Anfrage“ (gelb).
A2: Bereich | B2: Warengruppe | C2: Produkt | D2: Prüfblock | E2: Prüfungsart | F2: SAP-Code | G2: Norm / Prüfprogramm | H2: Titel der Norm | I2: in Anlehnung an | J2: Anwendungsbereich | K2: Kosten 1. Prüfung | L2: Kosten je weiterem Produkt | M2: Kennz. | N2: BDA | O2: Bemerkung zur Norm | P2: PG-ID
B3: Grills u. Feuerstellen | C3: Feuerrohr | D3: Sicherheit-/Normprüfung | G3: in Anlehnung an EK5/AK8 17-12.01:2017 | I3: Nein | K3: 0 | M3: Nein | N3: Nein | P3: 4c8771d7-734d-4d2f-bffc-38bf089559e5
A4: Baumarkt | B4: Bewässerungsgeräte u. -systeme | C4: (Schlauch-)Verbinder | D4: Sicherheit-/Normprüfung | G4: EK5/AK8 13-05.02:2017 (Gartenbewässerungsartikel) | I4: Nein | K4: 720 | M4: Nein | N4: Nein | O4: CE-Kennzeichnung! KE nötig. | Verkaufsverpackung bereits im PRE-Test prüfen! Warnhinweise müssen vorhanden sein! | P4: 2485944d-4e9f-40dd-a345-9b29e0dbc6bf
A5: Baumarkt | B5: Bewässerungsgeräte u. -systeme | C5: Beregner | D5: Sicherheit-/Normprüfung | G5: EK5/AK8 13-05.02:2017 (Gartenbewässerungsartikel) | I5: Nein | K5: 1080 | M5: Nein | N5: Nein | O5: CE-Kennzeichnung! KE nötig. | Verkaufsverpackung bereits im PRE-Test prüfen! Warnhinweise müssen vorhanden sein! | P5: 069ad4a2-405c-4216-98cd-34abf3bb4553
A6: Baumarkt | B6: Bewässerungsgeräte u. -systeme | C6: Bewässerungscomputer | D6: Sicherheit-/Normprüfung | G6: Sicherheit / Normprüfung - Produktsicherheit Für E&E Produkte immer nur Kurzprüfungen im Labor Kosten richten sich Produktart EK5/AK8 13-05.02:2017 - Cl. 4.6 Überdruck - Cl. 4.7 Fallprüfung | I6: Nein | K6: 0 | M6: Nein | N6: Nein | O6: EE | P6: 301373e8-13f1-43a5-915e-a88c37b35d6d
A7: Baumarkt | B7: Bewässerungsgeräte u. -systeme | C7: Gartenbrause | D7: Sicherheit-/Normprüfung | G7: EK5/AK8 13-05.02:2017 (Gartenbewässerungsartikel) | I7: Nein | K7: 720 | M7: Nein | N7: Nein | O7: CE-Kennzeichnung! KE nötig. | Verkaufsverpackung bereits im PRE-Test prüfen! Warnhinweise müssen vorhanden sein! | P7: 26078af5-80ee-4c2a-a20e-e13f0d57dae8
A8: Baumarkt | B8: Gartenbewässerung (Sonstige) | C8: Drucksprüher <3L | D8: Sicherheit-/Normprüfung | G8: EN ISO 19932-1 & -2:2013 | I8: Nein | K8: 0 | M8: Nein | N8: Nein | O8: / :2022 ist noch im Entwurf | P8: fbc1894d-c0fd-46fd-bd8f-93eb730fcf7b
A9: Baumarkt | B9: Gartenbewässerung (Sonstige) | C9: Drucksprüher >3L | D9: Sicherheit-/Normprüfung | G9: EK5 / TA6 14-01:2023 (Drucksprühgerät >3L) | I9: Nein | K9: 720 | M9: Nein | N9: Nein | O9: CE-Kennzeichnung! KE nötig. Die Einstufung der Geräte erfolgt nach Artikel 9 der Druckgeräterichtlinie Punkt 8 Kunststoffe schriftliche Unbedenklichkeitserklärungen | P9: d842f471-3b48-4761-943f-453772f4d8eb
A10: Baumarkt | B10: Gartenbewässerung (Sonstige) | C10: Gießkanne | D10: Sicherheit-/Normprüfung | G10: 102_PPM | I10: Nein | K10: 180 | M10: Nein | N10: Nein | O10: PSA beachten! | ggf. EE | Multiwinkel / Lineal / Zollstock / usw. | nicht trivial, wenn Verwendung auf Herd möglich | HG | P10: 9210ed65-bfd0-418d-866b-8ba8c3c5167b
A11: Baumarkt | B11: Gartenbewässerung (Sonstige) | C11: Regentonne | D11: Sicherheit-/Normprüfung | G11: 102_PPM | I11: Nein | K11: 180 | M11: Nein | N11: Nein | O11: PSA beachten! | ggf. EE | Multiwinkel / Lineal / Zollstock / usw. | nicht trivial, wenn Verwendung auf Herd möglich | HG | P11: 6adbdef8-6479-4d9a-96de-bd7d7e870187
A12: Baumarkt | B12: Gartengeräte u. -zubehör (Sonstige) | C12: (Gewebe-)Planen | D12: Sicherheit-/Normprüfung | G12: 102_PPM | I12: Nein | K12: 540 | M12: Nein | N12: Nein | O12: PSA beachten! | ggf. EE | Multiwinkel / Lineal / Zollstock / usw. | nicht trivial, wenn Verwendung auf Herd möglich | HG | P12: f1b5500e-fda8-4344-aca0-8a6d8c195938
A13: Baumarkt | B13: Gartengeräte u. -zubehör (Sonstige) | C13: Bodenmesser | D13: Sicherheit-/Normprüfung | G13: 102_PPM | I13: Nein | K13: 0 | M13: Nein | N13: Nein | O13: PSA beachten! | ggf. EE | Multiwinkel / Lineal / Zollstock / usw. | nicht trivial, wenn Verwendung auf Herd möglich | HG | P13: 115b6bd0-52f6-4785-af23-689a42058cfa
A14: Baumarkt | B14: Gartengeräte u. -zubehör (Sonstige) | C14: Gartengerätehaus | D14: Sicherheit-/Normprüfung | G14: EK5/AK8 12-04.1:2012 | I14: Nein | K14: 0 | M14: Nein | N14: Nein | O14: Korrosionsbeständigkeit Metalle müssen korrosionsgeschützt (Lackierung, Pulverbeschichtung, verzinkt) sein. Aluminium gilt als korrosionsbeständig. Herstellernachweis für tragende Kunststoffteile Der Kunststoff muss UV- und temperaturbeständig (min. 60°C) sein. Es wird ausschließlich ein Nachweis (z.B. Datenblatt etc.) vom Kunststoffhersteller akzeptiert. | P14: f333567e-9dae-4373-95e8-20ab3b9c4aca
A15: Baumarkt | B15: Gartengeräte u. -zubehör (Sonstige) | C15: Gartensack | D15: Sicherheit-/Normprüfung | G15: 111_PPM | I15: Nein | K15: 0 | M15: Nein | N15: Nein | P15: b4438896-2af0-4744-9cd4-4ed1160266d2
A16: Baumarkt | B16: Gartengeräte u. -zubehör (Sonstige) | C16: Gartenzubehör | D16: Sicherheit-/Normprüfung | G16: 102_PPM | I16: Nein | K16: 540 | M16: Nein | N16: Nein | O16: PSA beachten! | ggf. EE | Multiwinkel / Lineal / Zollstock / usw. | nicht trivial, wenn Verwendung auf Herd möglich | HG | P16: 7b7cf5c3-1dcd-4aa5-8f75-446e647b3747
A17: Baumarkt | B17: Gartengeräte u. -zubehör (Sonstige) | C17: Gerätehalter | D17: Sicherheit-/Normprüfung | G17: 102_PPM | I17: Nein | K17: 0 | M17: Nein | N17: Nein | O17: PSA beachten! | ggf. EE | Multiwinkel / Lineal / Zollstock / usw. | nicht trivial, wenn Verwendung auf Herd möglich | HG | P17: a344ef39-c913-4a58-9354-a39b4de954f7
A18: Baumarkt | B18: Gartengeräte u. -zubehör (Sonstige) | C18: Kaminholzregal | D18: Sicherheit-/Normprüfung | G18: in Anlehnung an DIN EN 14749 | I18: Nein | K18: 0 | M18: Nein | N18: Nein | P18: 15495e0b-e72b-4043-ba9d-18398658dfd7
A19: Baumarkt | B19: Gartengeräte u. -zubehör (Sonstige) | C19: Kniekissen | D19: Sicherheit-/Normprüfung | G19: 102_PPM | I19: Nein | K19: 540 | M19: Nein | N19: Nein | O19: PSA beachten! | ggf. EE | Multiwinkel / Lineal / Zollstock / usw. | nicht trivial, wenn Verwendung auf Herd möglich | HG | P19: 9c269978-339e-4f8b-8a86-833f04cf4b41
A20: Baumarkt | B20: Gartengeräte u. -zubehör (Sonstige) | C20: Komposter | D20: Sicherheit-/Normprüfung | G20: 102_PPM | I20: Nein | K20: 0 | M20: Nein | N20: Nein | O20: PSA beachten! | ggf. EE | Multiwinkel / Lineal / Zollstock / usw. | nicht trivial, wenn Verwendung auf Herd möglich | HG | P20: 7266a5e1-c3b2-4bcd-ad61-732b77e42277
A21: Baumarkt | B21: Gartengeräte u. -zubehör (Sonstige) | C21: Kübel / Eimer | D21: Sicherheit-/Normprüfung | G21: 102_PPM + Belastungsprüfung (1,5-fache Nennlast für 60min.) | I21: Nein | K21: 0 | M21: Nein | N21: Nein | O21: für alle Eimer, die auf einer Baustelle verwendet werden können | P21: 67acbddf-35fa-4685-9768-d6c3c75a84c1
A22: Baumarkt | B22: Gartengeräte u. -zubehör (Sonstige) | C22: Pflanzenroller | D22: Sicherheit-/Normprüfung | G22: EK5/AK5 14-04.0-2014 | I22: Nein | K22: 0 | M22: Nein | N22: Nein | O22: Korrosion (EN ISO 4628-3) wenn Bauteile nicht durch Lackierung, Beschichtung , Werkstoffauswahl geschützt, Note Ri = 1 Künstliche Alterung bei Kunststoffbodenplatte ISO 4892 500h Kerbschlagbiegeprüfung (20% Reduzierung im Vergl. zur unbehandelten Probe) im EK gefordert: Typenschild + Herstellererklärung zur Tragfähigkeit der Rollen + der verwendeten Materialien | P22: 5bb25fa6-347c-4430-9b7d-a873d8b23c0a
A23: Baumarkt | B23: Gartengeräte u. -zubehör (Sonstige) | C23: Rasenkante | D23: Sicherheit-/Normprüfung | G23: 102_PPM | I23: Nein | K23: 0 | M23: Nein | N23: Nein | O23: PSA beachten! | ggf. EE | Multiwinkel / Lineal / Zollstock / usw. | nicht trivial, wenn Verwendung auf Herd möglich | HG | P23: 868f0d7b-3262-439b-baf1-692f10270d38
A24: Baumarkt | B24: Gartengeräte u. -zubehör (Sonstige) | C24: Tiervertreiber | D24: FFU/Fitting | G24: FFU laborintern ohne Probanden 30SER (70%/50%/10-30%) FFU Prüfung nach internem PPM (nur Falls im PA angegeben) Laborintern ohne Prüfung der Gebrauchstauglichkeit mittels Probanden. Es werden Punkte zur Funktionalität, Verarbeitungsqualität, Verständlichkeit der BDA geprüft) | I24: Nein | K24: 580 | M24: Nein | N24: Nein | P24: 23682bd0-1792-403b-b6c9-35f959ca99f8
A25: Baumarkt | B25: Gartengeräte u. -zubehör (Sonstige) | C25: Tiervertreiber | D25: Sicherheit-/Normprüfung | G25: Sicherheit / Normprüfung - Produktsicherheit Teilprüfung Anlehnung an 100_PPM - IP44 - Glühdraht Akku-Sicherheitskurzcheck Produkte mit Akku jeder Größe werden nach 163_PPM_TGS_REV_A_ Akku-Sicherheitskurzcheck Lidl geprüft | I25: Nein | K25: 0 | M25: Nein | N25: Nein | O25: Tiervertreiber Universal Sicherheit / Normprüfung - Produktsicherheit Für E&E Produkte immer nur Kurzprüfungen im Labor Anlehnung an 100_PPM - IP44 - Glühdraht 750€ Sicherheit / Normprüfung - Produktsicherheit Akku-Sicherheitskurzcheck Produkte mit Akku jeder Größe werden nach 163_PPM_TGS_REV_A_ Akku-Sicherheitskurzcheck Lidl geprüft 950€ Tiervertreiber Maulwurf Sicherheit / Normprüfung - Produktsicherheit Teilprüfung nach 0100_PPM - Kurzschluss - Erwärmung - Mech. Festigkeit - etc. 750€ | P25: 23682bd0-1792-403b-b6c9-35f959ca99f8
A26: Baumarkt | B26: Gartengeräte u. -zubehör (Sonstige) | C26: Trolley | D26: Sicherheit-/Normprüfung | G26: EK5/AK5 06-01.3:2011 | I26: Nein | K26: 0 | M26: Nein | N26: Nein | O26: UV-Beständigkeit Tragende Teile aus Kunststoff Korrosion nach DIN EN ISO 6270-2, 5 Zyklen nicht erfordlerlich bei galvanisch- oder pulverbeschichteten Bauteilen | P26: 6e8c7c0e-3e31-479a-9c6e-c36b7448425d
A27: Baumarkt | B27: Gartengeräte u. -zubehör (Sonstige) | C27: Vlies | D27: Sicherheit-/Normprüfung | G27: 102_PPM | I27: Nein | K27: 0 | M27: Nein | N27: Nein | O27: PSA beachten! | ggf. EE | Multiwinkel / Lineal / Zollstock / usw. | nicht trivial, wenn Verwendung auf Herd möglich | HG | P27: a9e4f9e3-5e74-45d3-bdb2-951ed7ac4b13
A28: Baumarkt | B28: Gartenhäuser | C28: Gartengerätehaus | D28: Sicherheit-/Normprüfung | G28: EK5/AK8 12-04.1:2012 | I28: Nein | M28: Nein | N28: Nein | O28: Korrosionsbeständigkeit Metalle müssen korrosionsgeschützt (Lackierung, Pulverbeschichtung, verzinkt) sein. Aluminium gilt als korrosionsbeständig. Herstellernachweis für tragende Kunststoffteile Der Kunststoff muss UV- und temperaturbeständig (min. 60°C) sein. Es wird ausschließlich ein Nachweis (z.B. Datenblatt etc.) vom Kunststoffhersteller akzeptiert. | P28: 80cdef55-dafc-4948-9284-ebec74f08d4a
A29: Baumarkt | B29: Gartenschläuche u. Aufroller | C29: Gartenschlauch | D29: FFU/Fitting | G29: 004_PPM_FFU | I29: Nein | K29: 600 | M29: Nein | N29: Nein | P29: 2175b528-824c-4821-a449-e9cf3d5b42bb
A30: Baumarkt | B30: Gartenschläuche u. Aufroller | C30: Gartenschlauch | D30: Sicherheit-/Normprüfung | G30: EK5/AK8 13-05.02:2017 (Gartenbewässerungsartikel) | I30: Nein | K30: 540 | M30: Nein | N30: Nein | O30: CE-Kennzeichnung! KE nötig. | Verkaufsverpackung bereits im PRE-Test prüfen! Warnhinweise müssen vorhanden sein! | P30: 2175b528-824c-4821-a449-e9cf3d5b42bb
A31: Baumarkt | B31: Gartenschläuche u. Aufroller | C31: Schlauchaufroller | D31: FFU/Fitting | G31: 038_PPM_FFU | I31: Nein | K31: 960 | M31: Nein | N31: Nein | P31: 33bc738e-f7be-4a24-ba8d-4097ee71b597
A32: Baumarkt | B32: Gartenschläuche u. Aufroller | C32: Schlauchaufroller | D32: Sicherheit-/Normprüfung | G32: EK5/AK8 13-05.02:2017 (Gartenbewässerungsartikel) | I32: Nein | K32: 540 | M32: Nein | N32: Nein | O32: CE-Kennzeichnung! KE nötig. | Verkaufsverpackung bereits im PRE-Test prüfen! Warnhinweise müssen vorhanden sein! | P32: 33bc738e-f7be-4a24-ba8d-4097ee71b597
A33: Baumarkt | B33: Gartenwerkzeug handgeführt u. Zubehör | C33: Erntehelfer | D33: Sicherheit-/Normprüfung | G33: 102_PPM | I33: Nein | K33: 0 | M33: Nein | N33: Nein | O33: PSA beachten! | ggf. EE | Multiwinkel / Lineal / Zollstock / usw. | nicht trivial, wenn Verwendung auf Herd möglich | HG | P33: 0ec4e4d1-dd15-47bd-b338-d37e78a6e6b9
A34: Baumarkt | B34: Gasgrills | C34: Gasgrill | D34: Sicherheit-/Normprüfung | G34: DIN EN 1860-1 | I34: Nein | K34: 0 | M34: Nein | N34: Nein | O34: Gasgeräteverordnung! CE-Zeichen! KE nötig. Prüfung über Asien | Für GS-Projekte EK-Beschlussliste EK5/AK8 beachten! | P34: 261cdf89-c63d-441f-9b62-f717b496993e
A35: Baumarkt | B35: Grillzubehör | C35: Anzündkamin | D35: Sicherheit-/Normprüfung | G35: in Anlehnung an DIN EN 1860-1 | I35: Nein | K35: 360 | M35: Nein | N35: Nein | P35: d33a5055-ad8b-4394-a48f-37e74f574bca
A36: Baumarkt | B36: Grillzubehör | C36: Feuerzeug | D36: Sicherheit-/Normprüfung | G36: ISO 22702 | I36: Nein | K36: 900 | M36: Nein | N36: Nein | P36: 2264c2ce-8d2e-4e02-82d6-fce51e04eb10
A37: Baumarkt | B37: Grillzubehör | C37: Grillabdeckung | D37: Sicherheit-/Normprüfung | G37: 102_PPM | I37: Nein | K37: 0 | M37: Nein | N37: Nein | O37: PSA beachten! | ggf. EE | Multiwinkel / Lineal / Zollstock / usw. | nicht trivial, wenn Verwendung auf Herd möglich | HG | P37: 2d679c74-d480-4f62-938d-0b2d2b388b68
A38: Baumarkt | B38: Grillzubehör | C38: Grillbürsten | D38: Sicherheit-/Normprüfung | G38: 102_PPM | I38: Nein | K38: 270 | M38: Nein | N38: Nein | O38: PSA beachten! | ggf. EE | Multiwinkel / Lineal / Zollstock / usw. | nicht trivial, wenn Verwendung auf Herd möglich | HG | P38: 4f7a4dad-e07a-4c34-8ae3-5a7ce7e6691d
A39: Baumarkt | B39: Grillzubehör | C39: Grillzubehör / Kaminzubehör | D39: Sicherheit-/Normprüfung | G39: 102_PPM | I39: Nein | K39: 540 | M39: Nein | N39: Nein | O39: PSA beachten! | ggf. EE | Multiwinkel / Lineal / Zollstock / usw. | nicht trivial, wenn Verwendung auf Herd möglich | HG | P39: 19aee4af-09bb-434c-b3b6-e68a7e544a97
A40: Baumarkt | B40: Kamine, Öfen u. Zubehör | C40: Kaminbesteck | D40: Sicherheit-/Normprüfung | G40: 102_PPM | I40: Nein | K40: 270 | M40: Nein | N40: Nein | O40: PSA beachten! | ggf. EE | Multiwinkel / Lineal / Zollstock / usw. | nicht trivial, wenn Verwendung auf Herd möglich | HG | P40: ee5dfac1-ce50-49b3-a13e-510cbb24f24e
...

Sheet Prüfgrundlagen
A1: Eine Zeile je Produkt: welche Prüfungen gefordert sind, wie viele Muster nötig sind und wie lange es dauert. Die drei Summenspalten sind Formeln über das Blatt „Prüfanforderungen“ und rechnen sich damit wie im Tool. Die Spalte „Status“ markiert Produkte ohne zugeordnete Norm und solche mit 0 € Kosten.
A2: Bereich | B2: Warengruppe | C2: WG-Code | D2: Produkt | E2: Status | F2: Trivial | G2: Anzahl Muster | H2: Bearbeitungs-dauer (AT) | I2: Kennz. | J2: BDA | K2: Normen Sicherheit/Norm | L2: Summe Sicherheit/Norm | M2: Kommentar Sicherheit/Norm | N2: Bemerkungen aus den Normen | O2: FFU-Normen | P2: Summe FFU | Q2: Kommentar FFU | R2: NGO/StiWa-Normen | S2: Summe NGO/StiWa | T2: Kommentar NGO/StiWa | U2: Kosten TP | V2: Kosten alt | W2: ID
B3: Grills u. Feuerstellen | C3: 370040 | D3: Feuerrohr | E3: =IF(COUNTIFS(Prüfanforderungen!$P$3:$P$181,$W3)=0,"keine Norm hinterlegt",IF($L3=0,"0 € hinterlegt","")) -> 0 € hinterlegt | F3: Nein | G3: 3 | I3: Nein | J3: Nein | K3: in Anlehnung an EK5/AK8 17-12.01:2017 | L3: =IF(COUNTIFS(Prüfanforderungen!$P$3:$P$181,$W3,Prüfanforderungen!$D$3:$D$181,"Sicherheit-/Normprüfung",Prüfanforderungen!$K$3:$K$181,">=0")=0,"Preis auf Anfrage",SUMIFS(Prüfanforderungen!$K$3:$K$181,Prüfanforderungen!$P$3:$P$181,$W3,Prüfanforderungen!$D$3:$D$181,"Sicherheit-/Normprüfung")) -> 0 | P3: =IF(COUNTIFS(Prüfanforderungen!$P$3:$P$181,$W3,Prüfanforderungen!$D$3:$D$181,"FFU/Fitting",Prüfanforderungen!$K$3:$K$181,">=0")=0,"Preis auf Anfrage",SUMIFS(Prüfanforderungen!$K$3:$K$181,Prüfanforderungen!$P$3:$P$181,$W3,Prüfanforderungen!$D$3:$D$181,"FFU/Fitting")) -> Preis auf Anfrage | S3: =IF(COUNTIFS(Prüfanforderungen!$P$3:$P$181,$W3,Prüfanforderungen!$D$3:$D$181,"NGO / StiWa",Prüfanforderungen!$K$3:$K$181,">=0")=0,"Preis auf Anfrage",SUMIFS(Prüfanforderungen!$K$3:$K$181,Prüfanforderungen!$P$3:$P$181,$W3,Prüfanforderungen!$D$3:$D$181,"NGO / StiWa")) -> Preis auf Anfrage | V3: 960 | W3: 4c8771d7-734d-4d2f-bffc-38bf089559e5
A4: Baumarkt | B4: Bewässerungsgeräte u. -systeme | C4: 372020 | D4: (Schlauch-)Verbinder | E4: =IF(COUNTIFS(Prüfanforderungen!$P$3:$P$181,$W4)=0,"keine Norm hinterlegt",IF($L4=0,"0 € hinterlegt","")) | F4: Nein | G4: 4 | I4: Nein | J4: Nein | K4: EK5/AK8 13-05.02:2017 (Gartenbewässerungsartikel) | L4: =IF(COUNTIFS(Prüfanforderungen!$P$3:$P$181,$W4,Prüfanforderungen!$D$3:$D$181,"Sicherheit-/Normprüfung",Prüfanforderungen!$K$3:$K$181,">=0")=0,"Preis auf Anfrage",SUMIFS(Prüfanforderungen!$K$3:$K$181,Prüfanforderungen!$P$3:$P$181,$W4,Prüfanforderungen!$D$3:$D$181,"Sicherheit-/Normprüfung")) -> 720 | N4: EK5/AK8 13-05.02:2017 (Gartenbewässerungsartikel): CE-Kennzeichnung! KE nötig. | Verkaufsverpackung bereits im PRE-Test prüfen! Warnhinweise müssen vorhanden sein! | P4: =IF(COUNTIFS(Prüfanforderungen!$P$3:$P$181,$W4,Prüfanforderungen!$D$3:$D$181,"FFU/Fitting",Prüfanforderungen!$K$3:$K$181,">=0")=0,"Preis auf Anfrage",SUMIFS(Prüfanforderungen!$K$3:$K$181,Prüfanforderungen!$P$3:$P$181,$W4,Prüfanforderungen!$D$3:$D$181,"FFU/Fitting")) -> Preis auf Anfrage | S4: =IF(COUNTIFS(Prüfanforderungen!$P$3:$P$181,$W4,Prüfanforderungen!$D$3:$D$181,"NGO / StiWa",Prüfanforderungen!$K$3:$K$181,">=0")=0,"Preis auf Anfrage",SUMIFS(Prüfanforderungen!$K$3:$K$181,Prüfanforderungen!$P$3:$P$181,$W4,Prüfanforderungen!$D$3:$D$181,"NGO / StiWa")) -> Preis auf Anfrage | V4: 960 | W4: 2485944d-4e9f-40dd-a345-9b29e0dbc6bf
A5: Baumarkt | B5: Bewässerungsgeräte u. -systeme | C5: 372020 | D5: Beregner | E5: =IF(COUNTIFS(Prüfanforderungen!$P$3:$P$181,$W5)=0,"keine Norm hinterlegt",IF($L5=0,"0 € hinterlegt","")) | F5: Nein | G5: 4 | I5: Nein | J5: Nein | K5: EK5/AK8 13-05.02:2017 (Gartenbewässerungsartikel) | L5: =IF(COUNTIFS(Prüfanforderungen!$P$3:$P$181,$W5,Prüfanforderungen!$D$3:$D$181,"Sicherheit-/Normprüfung",Prüfanforderungen!$K$3:$K$181,">=0")=0,"Preis auf Anfrage",SUMIFS(Prüfanforderungen!$K$3:$K$181,Prüfanforderungen!$P$3:$P$181,$W5,Prüfanforderungen!$D$3:$D$181,"Sicherheit-/Normprüfung")) -> 1080 | N5: EK5/AK8 13-05.02:2017 (Gartenbewässerungsartikel): CE-Kennzeichnung! KE nötig. | Verkaufsverpackung bereits im PRE-Test prüfen! Warnhinweise müssen vorhanden sein! | P5: =IF(COUNTIFS(Prüfanforderungen!$P$3:$P$181,$W5,Prüfanforderungen!$D$3:$D$181,"FFU/Fitting",Prüfanforderungen!$K$3:$K$181,">=0")=0,"Preis auf Anfrage",SUMIFS(Prüfanforderungen!$K$3:$K$181,Prüfanforderungen!$P$3:$P$181,$W5,Prüfanforderungen!$D$3:$D$181,"FFU/Fitting")) -> Preis auf Anfrage | S5: =IF(COUNTIFS(Prüfanforderungen!$P$3:$P$181,$W5,Prüfanforderungen!$D$3:$D$181,"NGO / StiWa",Prüfanforderungen!$K$3:$K$181,">=0")=0,"Preis auf Anfrage",SUMIFS(Prüfanforderungen!$K$3:$K$181,Prüfanforderungen!$P$3:$P$181,$W5,Prüfanforderungen!$D$3:$D$181,"NGO / StiWa")) -> Preis auf Anfrage | V5: 960 | W5: 069ad4a2-405c-4216-98cd-34abf3bb4553
A6: Baumarkt | B6: Bewässerungsgeräte u. -systeme | C6: 372020 | D6: Bewässerungscomputer | E6: =IF(COUNTIFS(Prüfanforderungen!$P$3:$P$181,$W6)=0,"keine Norm hinterlegt",IF($L6=0,"0 € hinterlegt","")) -> 0 € hinterlegt | F6: Nein | G6: 6 | I6: Nein | J6: Nein | K6: Sicherheit / Normprüfung - Produktsicherheit Für E&E Produkte immer nur Kurzprüfungen im Labor Kosten richten sich Produktart EK5/AK8 13-05.02:2017 - Cl. 4.6 Überdruck - Cl. 4.7 Fallprüfung | L6: =IF(COUNTIFS(Prüfanforderungen!$P$3:$P$181,$W6,Prüfanforderungen!$D$3:$D$181,"Sicherheit-/Normprüfung",Prüfanforderungen!$K$3:$K$181,">=0")=0,"Preis auf Anfrage",SUMIFS(Prüfanforderungen!$K$3:$K$181,Prüfanforderungen!$P$3:$P$181,$W6,Prüfanforderungen!$D$3:$D$181,"Sicherheit-/Normprüfung")) -> 0 | N6: Sicherheit / Normprüfung - Produktsicherheit Für E&E Produkte immer nur Kurzprüfungen im Labor Kosten richten sich Produktart EK5/AK8 13-05.02:2017 - Cl. 4.6 Überdruck - Cl. 4.7 Fallprüfung: EE | P6: =IF(COUNTIFS(Prüfanforderungen!$P$3:$P$181,$W6,Prüfanforderungen!$D$3:$D$181,"FFU/Fitting",Prüfanforderungen!$K$3:$K$181,">=0")=0,"Preis auf Anfrage",SUMIFS(Prüfanforderungen!$K$3:$K$181,Prüfanforderungen!$P$3:$P$181,$W6,Prüfanforderungen!$D$3:$D$181,"FFU/Fitting")) -> Preis auf Anfrage | S6: =IF(COUNTIFS(Prüfanforderungen!$P$3:$P$181,$W6,Prüfanforderungen!$D$3:$D$181,"NGO / StiWa",Prüfanforderungen!$K$3:$K$181,">=0")=0,"Preis auf Anfrage",SUMIFS(Prüfanforderungen!$K$3:$K$181,Prüfanforderungen!$P$3:$P$181,$W6,Prüfanforderungen!$D$3:$D$181,"NGO / StiWa")) -> Preis auf Anfrage | V6: 450 | W6: 301373e8-13f1-43a5-915e-a88c37b35d6d
A7: Baumarkt | B7: Bewässerungsgeräte u. -systeme | C7: 372020 | D7: Gartenbrause | E7: =IF(COUNTIFS(Prüfanforderungen!$P$3:$P$181,$W7)=0,"keine Norm hinterlegt",IF($L7=0,"0 € hinterlegt","")) | F7: Nein | G7: 4 | I7: Nein | J7: Nein | K7: EK5/AK8 13-05.02:2017 (Gartenbewässerungsartikel) | L7: =IF(COUNTIFS(Prüfanforderungen!$P$3:$P$181,$W7,Prüfanforderungen!$D$3:$D$181,"Sicherheit-/Normprüfung",Prüfanforderungen!$K$3:$K$181,">=0")=0,"Preis auf Anfrage",SUMIFS(Prüfanforderungen!$K$3:$K$181,Prüfanforderungen!$P$3:$P$181,$W7,Prüfanforderungen!$D$3:$D$181,"Sicherheit-/Normprüfung")) -> 720 | N7: EK5/AK8 13-05.02:2017 (Gartenbewässerungsartikel): CE-Kennzeichnung! KE nötig. | Verkaufsverpackung bereits im PRE-Test prüfen! Warnhinweise müssen vorhanden sein! | P7: =IF(COUNTIFS(Prüfanforderungen!$P$3:$P$181,$W7,Prüfanforderungen!$D$3:$D$181,"FFU/Fitting",Prüfanforderungen!$K$3:$K$181,">=0")=0,"Preis auf Anfrage",SUMIFS(Prüfanforderungen!$K$3:$K$181,Prüfanforderungen!$P$3:$P$181,$W7,Prüfanforderungen!$D$3:$D$181,"FFU/Fitting")) -> Preis auf Anfrage | S7: =IF(COUNTIFS(Prüfanforderungen!$P$3:$P$181,$W7,Prüfanforderungen!$D$3:$D$181,"NGO / StiWa",Prüfanforderungen!$K$3:$K$181,">=0")=0,"Preis auf Anfrage",SUMIFS(Prüfanforderungen!$K$3:$K$181,Prüfanforderungen!$P$3:$P$181,$W7,Prüfanforderungen!$D$3:$D$181,"NGO / StiWa")) -> Preis auf Anfrage | V7: 960 | W7: 26078af5-80ee-4c2a-a20e-e13f0d57dae8
A8: Baumarkt | B8: Gartenbewässerung (Sonstige) | C8: 372099 | D8: Drucksprüher <3L | E8: =IF(COUNTIFS(Prüfanforderungen!$P$3:$P$181,$W8)=0,"keine Norm hinterlegt",IF($L8=0,"0 € hinterlegt","")) -> 0 € hinterlegt | F8: Nein | G8: 5 | I8: Nein | J8: Nein | K8: EN ISO 19932-1 & -2:2013 | L8: =IF(COUNTIFS(Prüfanforderungen!$P$3:$P$181,$W8,Prüfanforderungen!$D$3:$D$181,"Sicherheit-/Normprüfung",Prüfanforderungen!$K$3:$K$181,">=0")=0,"Preis auf Anfrage",SUMIFS(Prüfanforderungen!$K$3:$K$181,Prüfanforderungen!$P$3:$P$181,$W8,Prüfanforderungen!$D$3:$D$181,"Sicherheit-/Normprüfung")) -> 0 | N8: EN ISO 19932-1 & -2:2013: / :2022 ist noch im Entwurf | P8: =IF(COUNTIFS(Prüfanforderungen!$P$3:$P$181,$W8,Prüfanforderungen!$D$3:$D$181,"FFU/Fitting",Prüfanforderungen!$K$3:$K$181,">=0")=0,"Preis auf Anfrage",SUMIFS(Prüfanforderungen!$K$3:$K$181,Prüfanforderungen!$P$3:$P$181,$W8,Prüfanforderungen!$D$3:$D$181,"FFU/Fitting")) -> Preis auf Anfrage | S8: =IF(COUNTIFS(Prüfanforderungen!$P$3:$P$181,$W8,Prüfanforderungen!$D$3:$D$181,"NGO / StiWa",Prüfanforderungen!$K$3:$K$181,">=0")=0,"Preis auf Anfrage",SUMIFS(Prüfanforderungen!$K$3:$K$181,Prüfanforderungen!$P$3:$P$181,$W8,Prüfanforderungen!$D$3:$D$181,"NGO / StiWa")) -> Preis auf Anfrage | V8: 1260 | W8: fbc1894d-c0fd-46fd-bd8f-93eb730fcf7b
A9: Baumarkt | B9: Gartenbewässerung (Sonstige) | C9: 372099 | D9: Drucksprüher >3L | E9: =IF(COUNTIFS(Prüfanforderungen!$P$3:$P$181,$W9)=0,"keine Norm hinterlegt",IF($L9=0,"0 € hinterlegt","")) | F9: Nein | G9: 5 | I9: Nein | J9: Nein | K9: EK5 / TA6 14-01:2023 (Drucksprühgerät >3L) | L9: =IF(COUNTIFS(Prüfanforderungen!$P$3:$P$181,$W9,Prüfanforderungen!$D$3:$D$181,"Sicherheit-/Normprüfung",Prüfanforderungen!$K$3:$K$181,">=0")=0,"Preis auf Anfrage",SUMIFS(Prüfanforderungen!$K$3:$K$181,Prüfanforderungen!$P$3:$P$181,$W9,Prüfanforderungen!$D$3:$D$181,"Sicherheit-/Normprüfung")) -> 720 | N9: EK5 / TA6 14-01:2023 (Drucksprühgerät >3L): CE-Kennzeichnung! KE nötig. Die Einstufung der Geräte erfolgt nach Artikel 9 der Druckgeräterichtlinie Punkt 8 Kunststoffe schriftliche Unbedenklichkeitserklärungen | P9: =IF(COUNTIFS(Prüfanforderungen!$P$3:$P$181,$W9,Prüfanforderungen!$D$3:$D$181,"FFU/Fitting",Prüfanforderungen!$K$3:$K$181,">=0")=0,"Preis auf Anfrage",SUMIFS(Prüfanforderungen!$K$3:$K$181,Prüfanforderungen!$P$3:$P$181,$W9,Prüfanforderungen!$D$3:$D$181,"FFU/Fitting")) -> Preis auf Anfrage | S9: =IF(COUNTIFS(Prüfanforderungen!$P$3:$P$181,$W9,Prüfanforderungen!$D$3:$D$181,"NGO / StiWa",Prüfanforderungen!$K$3:$K$181,">=0")=0,"Preis auf Anfrage",SUMIFS(Prüfanforderungen!$K$3:$K$181,Prüfanforderungen!$P$3:$P$181,$W9,Prüfanforderungen!$D$3:$D$181,"NGO / StiWa")) -> Preis auf Anfrage | V9: 960 | W9: d842f471-3b48-4761-943f-453772f4d8eb
A10: Baumarkt | B10: Gartenbewässerung (Sonstige) | C10: 372099 | D10: Gießkanne | E10: =IF(COUNTIFS(Prüfanforderungen!$P$3:$P$181,$W10)=0,"keine Norm hinterlegt",IF($L10=0,"0 € hinterlegt","")) | F10: Ja | G10: 2 | I10: Nein | J10: Nein | K10: 102_PPM | L10: =IF(COUNTIFS(Prüfanforderungen!$P$3:$P$181,$W10,Prüfanforderungen!$D$3:$D$181,"Sicherheit-/Normprüfung",Prüfanforderungen!$K$3:$K$181,">=0")=0,"Preis auf Anfrage",SUMIFS(Prüfanforderungen!$K$3:$K$181,Prüfanforderungen!$P$3:$P$181,$W10,Prüfanforderungen!$D$3:$D$181,"Sicherheit-/Normprüfung")) -> 180 | N10: 102_PPM: PSA beachten! | ggf. EE | Multiwinkel / Lineal / Zollstock / usw. | nicht trivial, wenn Verwendung auf Herd möglich | HG | P10: =IF(COUNTIFS(Prüfanforderungen!$P$3:$P$181,$W10,Prüfanforderungen!$D$3:$D$181,"FFU/Fitting",Prüfanforderungen!$K$3:$K$181,">=0")=0,"Preis auf Anfrage",SUMIFS(Prüfanforderungen!$K$3:$K$181,Prüfanforderungen!$P$3:$P$181,$W10,Prüfanforderungen!$D$3:$D$181,"FFU/Fitting")) -> Preis auf Anfrage | S10: =IF(COUNTIFS(Prüfanforderungen!$P$3:$P$181,$W10,Prüfanforderungen!$D$3:$D$181,"NGO / StiWa",Prüfanforderungen!$K$3:$K$181,">=0")=0,"Preis auf Anfrage",SUMIFS(Prüfanforderungen!$K$3:$K$181,Prüfanforderungen!$P$3:$P$181,$W10,Prüfanforderungen!$D$3:$D$181,"NGO / StiWa")) -> Preis auf Anfrage | V10: 360 | W10: 9210ed65-bfd0-418d-866b-8ba8c3c5167b
A11: Baumarkt | B11: Gartenbewässerung (Sonstige) | C11: 372099 | D11: Regentonne | E11: =IF(COUNTIFS(Prüfanforderungen!$P$3:$P$181,$W11)=0,"keine Norm hinterlegt",IF($L11=0,"0 € hinterlegt","")) | F11: Ja | I11: Nein | J11: Nein | K11: 102_PPM | L11: =IF(COUNTIFS(Prüfanforderungen!$P$3:$P$181,$W11,Prüfanforderungen!$D$3:$D$181,"Sicherheit-/Normprüfung",Prüfanforderungen!$K$3:$K$181,">=0")=0,"Preis auf Anfrage",SUMIFS(Prüfanforderungen!$K$3:$K$181,Prüfanforderungen!$P$3:$P$181,$W11,Prüfanforderungen!$D$3:$D$181,"Sicherheit-/Normprüfung")) -> 180 | N11: 102_PPM: PSA beachten! | ggf. EE | Multiwinkel / Lineal / Zollstock / usw. | nicht trivial, wenn Verwendung auf Herd möglich | HG | P11: =IF(COUNTIFS(Prüfanforderungen!$P$3:$P$181,$W11,Prüfanforderungen!$D$3:$D$181,"FFU/Fitting",Prüfanforderungen!$K$3:$K$181,">=0")=0,"Preis auf Anfrage",SUMIFS(Prüfanforderungen!$K$3:$K$181,Prüfanforderungen!$P$3:$P$181,$W11,Prüfanforderungen!$D$3:$D$181,"FFU/Fitting")) -> Preis auf Anfrage | S11: =IF(COUNTIFS(Prüfanforderungen!$P$3:$P$181,$W11,Prüfanforderungen!$D$3:$D$181,"NGO / StiWa",Prüfanforderungen!$K$3:$K$181,">=0")=0,"Preis auf Anfrage",SUMIFS(Prüfanforderungen!$K$3:$K$181,Prüfanforderungen!$P$3:$P$181,$W11,Prüfanforderungen!$D$3:$D$181,"NGO / StiWa")) -> Preis auf Anfrage | W11: 6adbdef8-6479-4d9a-96de-bd7d7e870187
A12: Baumarkt | B12: Gartengeräte u. -zubehör (Sonstige) | C12: 371099 | D12: (Gewebe-)Planen | E12: =IF(COUNTIFS(Prüfanforderungen!$P$3:$P$181,$W12)=0,"keine Norm hinterlegt",IF($L12=0,"0 € hinterlegt","")) | F12: Ja | G12: 2 | I12: Nein | J12: Nein | K12: 102_PPM | L12: =IF(COUNTIFS(Prüfanforderungen!$P$3:$P$181,$W12,Prüfanforderungen!$D$3:$D$181,"Sicherheit-/Normprüfung",Prüfanforderungen!$K$3:$K$181,">=0")=0,"Preis auf Anfrage",SUMIFS(Prüfanforderungen!$K$3:$K$181,Prüfanforderungen!$P$3:$P$181,$W12,Prüfanforderungen!$D$3:$D$181,"Sicherheit-/Normprüfung")) -> 540 | N12: 102_PPM: PSA beachten! | ggf. EE | Multiwinkel / Lineal / Zollstock / usw. | nicht trivial, wenn Verwendung auf Herd möglich | HG | P12: =IF(COUNTIFS(Prüfanforderungen!$P$3:$P$181,$W12,Prüfanforderungen!$D$3:$D$181,"FFU/Fitting",Prüfanforderungen!$K$3:$K$181,">=0")=0,"Preis auf Anfrage",SUMIFS(Prüfanforderungen!$K$3:$K$181,Prüfanforderungen!$P$3:$P$181,$W12,Prüfanforderungen!$D$3:$D$181,"FFU/Fitting")) -> Preis auf Anfrage | S12: =IF(COUNTIFS(Prüfanforderungen!$P$3:$P$181,$W12,Prüfanforderungen!$D$3:$D$181,"NGO / StiWa",Prüfanforderungen!$K$3:$K$181,">=0")=0,"Preis auf Anfrage",SUMIFS(Prüfanforderungen!$K$3:$K$181,Prüfanforderungen!$P$3:$P$181,$W12,Prüfanforderungen!$D$3:$D$181,"NGO / StiWa")) -> Preis auf Anfrage | V12: 360 | W12: f1b5500e-fda8-4344-aca0-8a6d8c195938
A13: Baumarkt | B13: Gartengeräte u. -zubehör (Sonstige) | C13: 371099 | D13: Bodenmesser | E13: =IF(COUNTIFS(Prüfanforderungen!$P$3:$P$181,$W13)=0,"keine Norm hinterlegt",IF($L13=0,"0 € hinterlegt","")) -> 0 € hinterlegt | F13: Ja | G13: 2 | I13: Nein | J13: Nein | K13: 102_PPM | L13: =IF(COUNTIFS(Prüfanforderungen!$P$3:$P$181,$W13,Prüfanforderungen!$D$3:$D$181,"Sicherheit-/Normprüfung",Prüfanforderungen!$K$3:$K$181,">=0")=0,"Preis auf Anfrage",SUMIFS(Prüfanforderungen!$K$3:$K$181,Prüfanforderungen!$P$3:$P$181,$W13,Prüfanforderungen!$D$3:$D$181,"Sicherheit-/Normprüfung")) -> 0 | N13: 102_PPM: PSA beachten! | ggf. EE | Multiwinkel / Lineal / Zollstock / usw. | nicht trivial, wenn Verwendung auf Herd möglich | HG | P13: =IF(COUNTIFS(Prüfanforderungen!$P$3:$P$181,$W13,Prüfanforderungen!$D$3:$D$181,"FFU/Fitting",Prüfanforderungen!$K$3:$K$181,">=0")=0,"Preis auf Anfrage",SUMIFS(Prüfanforderungen!$K$3:$K$181,Prüfanforderungen!$P$3:$P$181,$W13,Prüfanforderungen!$D$3:$D$181,"FFU/Fitting")) -> Preis auf Anfrage | S13: =IF(COUNTIFS(Prüfanforderungen!$P$3:$P$181,$W13,Prüfanforderungen!$D$3:$D$181,"NGO / StiWa",Prüfanforderungen!$K$3:$K$181,">=0")=0,"Preis auf Anfrage",SUMIFS(Prüfanforderungen!$K$3:$K$181,Prüfanforderungen!$P$3:$P$181,$W13,Prüfanforderungen!$D$3:$D$181,"NGO / StiWa")) -> Preis auf Anfrage | V13: 360 | W13: 115b6bd0-52f6-4785-af23-689a42058cfa
A14: Baumarkt | B14: Gartengeräte u. -zubehör (Sonstige) | C14: 371099 | D14: Gartengerätehaus | E14: =IF(COUNTIFS(Prüfanforderungen!$P$3:$P$181,$W14)=0,"keine Norm hinterlegt",IF($L14=0,"0 € hinterlegt","")) -> 0 € hinterlegt | F14: Nein | G14: 2 | I14: Nein | J14: Nein | K14: EK5/AK8 12-04.1:2012 | L14: =IF(COUNTIFS(Prüfanforderungen!$P$3:$P$181,$W14,Prüfanforderungen!$D$3:$D$181,"Sicherheit-/Normprüfung",Prüfanforderungen!$K$3:$K$181,">=0")=0,"Preis auf Anfrage",SUMIFS(Prüfanforderungen!$K$3:$K$181,Prüfanforderungen!$P$3:$P$181,$W14,Prüfanforderungen!$D$3:$D$181,"Sicherheit-/Normprüfung")) -> 0 | N14: EK5/AK8 12-04.1:2012: Korrosionsbeständigkeit Metalle müssen korrosionsgeschützt (Lackierung, Pulverbeschichtung, verzinkt) sein. Aluminium gilt als korrosionsbeständig. Herstellernachweis für tragende Kunststoffteile Der Kunststoff muss UV- und temperaturbeständig (min. 60°C) sein. Es wird ausschließlich ein Nachweis (z.B. Datenblatt etc.) vom Kunststoffhersteller akzeptiert. | P14: =IF(COUNTIFS(Prüfanforderungen!$P$3:$P$181,$W14,Prüfanforderungen!$D$3:$D$181,"FFU/Fitting",Prüfanforderungen!$K$3:$K$181,">=0")=0,"Preis auf Anfrage",SUMIFS(Prüfanforderungen!$K$3:$K$181,Prüfanforderungen!$P$3:$P$181,$W14,Prüfanforderungen!$D$3:$D$181,"FFU/Fitting")) -> Preis auf Anfrage | S14: =IF(COUNTIFS(Prüfanforderungen!$P$3:$P$181,$W14,Prüfanforderungen!$D$3:$D$181,"NGO / StiWa",Prüfanforderungen!$K$3:$K$181,">=0")=0,"Preis auf Anfrage",SUMIFS(Prüfanforderungen!$K$3:$K$181,Prüfanforderungen!$P$3:$P$181,$W14,Prüfanforderungen!$D$3:$D$181,"NGO / StiWa")) -> Preis auf Anfrage | V14: 960 | W14: f333567e-9dae-4373-95e8-20ab3b9c4aca
A15: Baumarkt | B15: Gartengeräte u. -zubehör (Sonstige) | C15: 371099 | D15: Gartensack | E15: =IF(COUNTIFS(Prüfanforderungen!$P$3:$P$181,$W15)=0,"keine Norm hinterlegt",IF($L15=0,"0 € hinterlegt","")) -> 0 € hinterlegt | F15: Nein | G15: 2 | I15: Nein | J15: Nein | K15: 111_PPM | L15: =IF(COUNTIFS(Prüfanforderungen!$P$3:$P$181,$W15,Prüfanforderungen!$D$3:$D$181,"Sicherheit-/Normprüfung",Prüfanforderungen!$K$3:$K$181,">=0")=0,"Preis auf Anfrage",SUMIFS(Prüfanforderungen!$K$3:$K$181,Prüfanforderungen!$P$3:$P$181,$W15,Prüfanforderungen!$D$3:$D$181,"Sicherheit-/Normprüfung")) -> 0 | P15: =IF(COUNTIFS(Prüfanforderungen!$P$3:$P$181,$W15,Prüfanforderungen!$D$3:$D$181,"FFU/Fitting",Prüfanforderungen!$K$3:$K$181,">=0")=0,"Preis auf Anfrage",SUMIFS(Prüfanforderungen!$K$3:$K$181,Prüfanforderungen!$P$3:$P$181,$W15,Prüfanforderungen!$D$3:$D$181,"FFU/Fitting")) -> Preis auf Anfrage | S15: =IF(COUNTIFS(Prüfanforderungen!$P$3:$P$181,$W15,Prüfanforderungen!$D$3:$D$181,"NGO / StiWa",Prüfanforderungen!$K$3:$K$181,">=0")=0,"Preis auf Anfrage",SUMIFS(Prüfanforderungen!$K$3:$K$181,Prüfanforderungen!$P$3:$P$181,$W15,Prüfanforderungen!$D$3:$D$181,"NGO / StiWa")) -> Preis auf Anfrage | V15: 480 | W15: b4438896-2af0-4744-9cd4-4ed1160266d2
A16: Baumarkt | B16: Gartengeräte u. -zubehör (Sonstige) | C16: 371099 | D16: Gartenzubehör | E16: =IF(COUNTIFS(Prüfanforderungen!$P$3:$P$181,$W16)=0,"keine Norm hinterlegt",IF($L16=0,"0 € hinterlegt","")) | F16: Ja | G16: 2 | I16: Nein | J16: Nein | K16: 102_PPM | L16: =IF(COUNTIFS(Prüfanforderungen!$P$3:$P$181,$W16,Prüfanforderungen!$D$3:$D$181,"Sicherheit-/Normprüfung",Prüfanforderungen!$K$3:$K$181,">=0")=0,"Preis auf Anfrage",SUMIFS(Prüfanforderungen!$K$3:$K$181,Prüfanforderungen!$P$3:$P$181,$W16,Prüfanforderungen!$D$3:$D$181,"Sicherheit-/Normprüfung")) -> 540 | N16: 102_PPM: PSA beachten! | ggf. EE | Multiwinkel / Lineal / Zollstock / usw. | nicht trivial, wenn Verwendung auf Herd möglich | HG | P16: =IF(COUNTIFS(Prüfanforderungen!$P$3:$P$181,$W16,Prüfanforderungen!$D$3:$D$181,"FFU/Fitting",Prüfanforderungen!$K$3:$K$181,">=0")=0,"Preis auf Anfrage",SUMIFS(Prüfanforderungen!$K$3:$K$181,Prüfanforderungen!$P$3:$P$181,$W16,Prüfanforderungen!$D$3:$D$181,"FFU/Fitting")) -> Preis auf Anfrage | S16: =IF(COUNTIFS(Prüfanforderungen!$P$3:$P$181,$W16,Prüfanforderungen!$D$3:$D$181,"NGO / StiWa",Prüfanforderungen!$K$3:$K$181,">=0")=0,"Preis auf Anfrage",SUMIFS(Prüfanforderungen!$K$3:$K$181,Prüfanforderungen!$P$3:$P$181,$W16,Prüfanforderungen!$D$3:$D$181,"NGO / StiWa")) -> Preis auf Anfrage | V16: 480 | W16: 7b7cf5c3-1dcd-4aa5-8f75-446e647b3747
A17: Baumarkt | B17: Gartengeräte u. -zubehör (Sonstige) | C17: 371099 | D17: Gerätehalter | E17: =IF(COUNTIFS(Prüfanforderungen!$P$3:$P$181,$W17)=0,"keine Norm hinterlegt",IF($L17=0,"0 € hinterlegt","")) -> 0 € hinterlegt | F17: Ja | G17: 2 | I17: Nein | J17: Nein | K17: 102_PPM | L17: =IF(COUNTIFS(Prüfanforderungen!$P$3:$P$181,$W17,Prüfanforderungen!$D$3:$D$181,"Sicherheit-/Normprüfung",Prüfanforderungen!$K$3:$K$181,">=0")=0,"Preis auf Anfrage",SUMIFS(Prüfanforderungen!$K$3:$K$181,Prüfanforderungen!$P$3:$P$181,$W17,Prüfanforderungen!$D$3:$D$181,"Sicherheit-/Normprüfung")) -> 0 | N17: 102_PPM: PSA beachten! | ggf. EE | Multiwinkel / Lineal / Zollstock / usw. | nicht trivial, wenn Verwendung auf Herd möglich | HG | P17: =IF(COUNTIFS(Prüfanforderungen!$P$3:$P$181,$W17,Prüfanforderungen!$D$3:$D$181,"FFU/Fitting",Prüfanforderungen!$K$3:$K$181,">=0")=0,"Preis auf Anfrage",SUMIFS(Prüfanforderungen!$K$3:$K$181,Prüfanforderungen!$P$3:$P$181,$W17,Prüfanforderungen!$D$3:$D$181,"FFU/Fitting")) -> Preis auf Anfrage | S17: =IF(COUNTIFS(Prüfanforderungen!$P$3:$P$181,$W17,Prüfanforderungen!$D$3:$D$181,"NGO / StiWa",Prüfanforderungen!$K$3:$K$181,">=0")=0,"Preis auf Anfrage",SUMIFS(Prüfanforderungen!$K$3:$K$181,Prüfanforderungen!$P$3:$P$181,$W17,Prüfanforderungen!$D$3:$D$181,"NGO / StiWa")) -> Preis auf Anfrage | V17: 360 | W17: a344ef39-c913-4a58-9354-a39b4de954f7
A18: Baumarkt | B18: Gartengeräte u. -zubehör (Sonstige) | C18: 371099 | D18: Kaminholzregal | E18: =IF(COUNTIFS(Prüfanforderungen!$P$3:$P$181,$W18)=0,"keine Norm hinterlegt",IF($L18=0,"0 € hinterlegt","")) -> 0 € hinterlegt | F18: Nein | G18: 2 | I18: Nein | J18: Nein | K18: in Anlehnung an DIN EN 14749 | L18: =IF(COUNTIFS(Prüfanforderungen!$P$3:$P$181,$W18,Prüfanforderungen!$D$3:$D$181,"Sicherheit-/Normprüfung",Prüfanforderungen!$K$3:$K$181,">=0")=0,"Preis auf Anfrage",SUMIFS(Prüfanforderungen!$K$3:$K$181,Prüfanforderungen!$P$3:$P$181,$W18,Prüfanforderungen!$D$3:$D$181,"Sicherheit-/Normprüfung")) -> 0 | P18: =IF(COUNTIFS(Prüfanforderungen!$P$3:$P$181,$W18,Prüfanforderungen!$D$3:$D$181,"FFU/Fitting",Prüfanforderungen!$K$3:$K$181,">=0")=0,"Preis auf Anfrage",SUMIFS(Prüfanforderungen!$K$3:$K$181,Prüfanforderungen!$P$3:$P$181,$W18,Prüfanforderungen!$D$3:$D$181,"FFU/Fitting")) -> Preis auf Anfrage | S18: =IF(COUNTIFS(Prüfanforderungen!$P$3:$P$181,$W18,Prüfanforderungen!$D$3:$D$181,"NGO / StiWa",Prüfanforderungen!$K$3:$K$181,">=0")=0,"Preis auf Anfrage",SUMIFS(Prüfanforderungen!$K$3:$K$181,Prüfanforderungen!$P$3:$P$181,$W18,Prüfanforderungen!$D$3:$D$181,"NGO / StiWa")) -> Preis auf Anfrage | V18: 600 | W18: 15495e0b-e72b-4043-ba9d-18398658dfd7
A19: Baumarkt | B19: Gartengeräte u. -zubehör (Sonstige) | C19: 371099 | D19: Kniekissen | E19: =IF(COUNTIFS(Prüfanforderungen!$P$3:$P$181,$W19)=0,"keine Norm hinterlegt",IF($L19=0,"0 € hinterlegt","")) | F19: Ja | G19: 2 | I19: Nein | J19: Nein | K19: 102_PPM | L19: =IF(COUNTIFS(Prüfanforderungen!$P$3:$P$181,$W19,Prüfanforderungen!$D$3:$D$181,"Sicherheit-/Normprüfung",Prüfanforderungen!$K$3:$K$181,">=0")=0,"Preis auf Anfrage",SUMIFS(Prüfanforderungen!$K$3:$K$181,Prüfanforderungen!$P$3:$P$181,$W19,Prüfanforderungen!$D$3:$D$181,"Sicherheit-/Normprüfung")) -> 540 | N19: 102_PPM: PSA beachten! | ggf. EE | Multiwinkel / Lineal / Zollstock / usw. | nicht trivial, wenn Verwendung auf Herd möglich | HG | P19: =IF(COUNTIFS(Prüfanforderungen!$P$3:$P$181,$W19,Prüfanforderungen!$D$3:$D$181,"FFU/Fitting",Prüfanforderungen!$K$3:$K$181,">=0")=0,"Preis auf Anfrage",SUMIFS(Prüfanforderungen!$K$3:$K$181,Prüfanforderungen!$P$3:$P$181,$W19,Prüfanforderungen!$D$3:$D$181,"FFU/Fitting")) -> Preis auf Anfrage | S19: =IF(COUNTIFS(Prüfanforderungen!$P$3:$P$181,$W19,Prüfanforderungen!$D$3:$D$181,"NGO / StiWa",Prüfanforderungen!$K$3:$K$181,">=0")=0,"Preis auf Anfrage",SUMIFS(Prüfanforderungen!$K$3:$K$181,Prüfanforderungen!$P$3:$P$181,$W19,Prüfanforderungen!$D$3:$D$181,"NGO / StiWa")) -> Preis auf Anfrage | V19: 480 | W19: 9c269978-339e-4f8b-8a86-833f04cf4b41
A20: Baumarkt | B20: Gartengeräte u. -zubehör (Sonstige) | C20: 371099 | D20: Komposter | E20: =IF(COUNTIFS(Prüfanforderungen!$P$3:$P$181,$W20)=0,"keine Norm hinterlegt",IF($L20=0,"0 € hinterlegt","")) -> 0 € hinterlegt | F20: Ja | G20: 2 | I20: Nein | J20: Nein | K20: 102_PPM | L20: =IF(COUNTIFS(Prüfanforderungen!$P$3:$P$181,$W20,Prüfanforderungen!$D$3:$D$181,"Sicherheit-/Normprüfung",Prüfanforderungen!$K$3:$K$181,">=0")=0,"Preis auf Anfrage",SUMIFS(Prüfanforderungen!$K$3:$K$181,Prüfanforderungen!$P$3:$P$181,$W20,Prüfanforderungen!$D$3:$D$181,"Sicherheit-/Normprüfung")) -> 0 | N20: 102_PPM: PSA beachten! | ggf. EE | Multiwinkel / Lineal / Zollstock / usw. | nicht trivial, wenn Verwendung auf Herd möglich | HG | P20: =IF(COUNTIFS(Prüfanforderungen!$P$3:$P$181,$W20,Prüfanforderungen!$D$3:$D$181,"FFU/Fitting",Prüfanforderungen!$K$3:$K$181,">=0")=0,"Preis auf Anfrage",SUMIFS(Prüfanforderungen!$K$3:$K$181,Prüfanforderungen!$P$3:$P$181,$W20,Prüfanforderungen!$D$3:$D$181,"FFU/Fitting")) -> Preis auf Anfrage | S20: =IF(COUNTIFS(Prüfanforderungen!$P$3:$P$181,$W20,Prüfanforderungen!$D$3:$D$181,"NGO / StiWa",Prüfanforderungen!$K$3:$K$181,">=0")=0,"Preis auf Anfrage",SUMIFS(Prüfanforderungen!$K$3:$K$181,Prüfanforderungen!$P$3:$P$181,$W20,Prüfanforderungen!$D$3:$D$181,"NGO / StiWa")) -> Preis auf Anfrage | V20: 360 | W20: 7266a5e1-c3b2-4bcd-ad61-732b77e42277
